/opt/conda/conda-bld/pytorch_1607370141920/work/aten/src/THCUNN/ClassNLLCriterion.cu:108: cunn_ClassNLLCriterion_updateOutput_kernel: block: [0,0,0], thread: [0,0,0] Assertion `t >= 0 && t < n_classes` failed.
/opt/conda/conda-bld/pytorch_1607370141920/work/aten/src/THCUNN/ClassNLLCriterion.cu:108: cunn_ClassNLLCriterion_updateOutput_kernel: block: [0,0,0], thread: [2,0,0] Assertion `t >= 0 && t < n_classes` failed.
/opt/conda/conda-bld/pytorch_1607370141920/work/aten/src/THCUNN/ClassNLLCriterion.cu:108: cunn_ClassNLLCriterion_updateOutput_kernel: block: [0,0,0], thread: [3,0,0] Assertion `t >= 0 && t < n_classes` failed.
/opt/conda/conda-bld/pytorch_1607370141920/work/aten/src/THCUNN/ClassNLLCriterion.cu:108: cunn_ClassNLLCriterion_updateOutput_kernel: block: [0,0,0], thread: [8,0,0] Assertion `t >= 0 && t < n_classes` failed.
/opt/conda/conda-bld/pytorch_1607370141920/work/aten/src/THCUNN/ClassNLLCriterion.cu:108: cunn_ClassNLLCriterion_updateOutput_kernel: block: [0,0,0], thread: [11,0,0] Assertion `t >= 0 && t < n_classes` failed.
/opt/conda/conda-bld/pytorch_1607370141920/work/aten/src/THCUNN/ClassNLLCriterion.cu:108: cunn_ClassNLLCriterion_updateOutput_kernel: block: [0,0,0], thread: [14,0,0] Assertion `t >= 0 && t < n_classes` failed.
/opt/conda/conda-bld/pytorch_1607370141920/work/aten/src/THCUNN/ClassNLLCriterion.cu:108: cunn_ClassNLLCriterion_updateOutput_kernel: block: [0,0,0], thread: [15,0,0] Assertion `t >= 0 && t < n_classes` failed.
/opt/conda/conda-bld/pytorch_1607370141920/work/aten/src/THCUNN/ClassNLLCriterion.cu:108: cunn_ClassNLLCriterion_updateOutput_kernel: block: [0,0,0], thread: [18,0,0] Assertion `t >= 0 && t < n_classes` failed.
/opt/conda/conda-bld/pytorch_1607370141920/work/aten/src/THCUNN/ClassNLLCriterion.cu:108: cunn_ClassNLLCriterion_updateOutput_kernel: block: [0,0,0], thread: [19,0,0] Assertion `t >= 0 && t < n_classes` failed.
/opt/conda/conda-bld/pytorch_1607370141920/work/aten/src/THCUNN/ClassNLLCriterion.cu:108: cunn_ClassNLLCriterion_updateOutput_kernel: block: [0,0,0], thread: [20,0,0] Assertion `t >= 0 && t < n_classes` failed.
/opt/conda/conda-bld/pytorch_1607370141920/work/aten/src/THCUNN/ClassNLLCriterion.cu:108: cunn_ClassNLLCriterion_updateOutput_kernel: block: [0,0,0], thread: [22,0,0] Assertion `t >= 0 && t < n_classes` failed.
/opt/conda/conda-bld/pytorch_1607370141920/work/aten/src/THCUNN/ClassNLLCriterion.cu:108: cunn_ClassNLLCriterion_updateOutput_kernel: block: [0,0,0], thread: [24,0,0] Assertion `t >= 0 && t < n_classes` failed.
/opt/conda/conda-bld/pytorch_1607370141920/work/aten/src/THCUNN/ClassNLLCriterion.cu:108: cunn_ClassNLLCriterion_updateOutput_kernel: block: [0,0,0], thread: [25,0,0] Assertion `t >= 0 && t < n_classes` failed.
/opt/conda/conda-bld/pytorch_1607370141920/work/aten/src/THCUNN/ClassNLLCriterion.cu:108: cunn_ClassNLLCriterion_updateOutput_kernel: block: [0,0,0], thread: [26,0,0] Assertion `t >= 0 && t < n_classes` failed.
/opt/conda/conda-bld/pytorch_1607370141920/work/aten/src/THCUNN/ClassNLLCriterion.cu:108: cunn_ClassNLLCriterion_updateOutput_kernel: block: [0,0,0], thread: [28,0,0] Assertion `t >= 0 && t < n_classes` failed.
/opt/conda/conda-bld/pytorch_1607370141920/work/aten/src/THCUNN/ClassNLLCriterion.cu:108: cunn_ClassNLLCriterion_updateOutput_kernel: block: [0,0,0], thread: [30,0,0] Assertion `t >= 0 && t < n_classes` failed.
Traceback (most recent call last):
  File "train_da.py", line 838, in <module>
    train(config)
  File "train_da.py", line 234, in train
    model, optimizer, lr_scheduler = pretrain(model, optimizer, sources[0], original_target_name, lr_scheduler, epochs=config['pre_train'], log=True, writer=writer)
  File "train_da.py", line 109, in pretrain
    meta_train=False, mark=0)
  File "/root/anaconda3/envs/pytorch/lib/python3.7/site-packages/torch/nn/modules/module.py", line 727, in _call_impl
    result = self.forward(*input, **kwargs)
  File "/root/anaconda3/envs/pytorch/lib/python3.7/site-packages/torch/nn/parallel/data_parallel.py", line 161, in forward
    outputs = self.parallel_apply(replicas, inputs, kwargs)
  File "/root/anaconda3/envs/pytorch/lib/python3.7/site-packages/torch/nn/parallel/data_parallel.py", line 171, in parallel_apply
    return parallel_apply(replicas, inputs, kwargs, self.device_ids[:len(replicas)])
  File "/root/anaconda3/envs/pytorch/lib/python3.7/site-packages/torch/nn/parallel/parallel_apply.py", line 86, in parallel_apply
    output.reraise()
  File "/root/anaconda3/envs/pytorch/lib/python3.7/site-packages/torch/_utils.py", line 428, in reraise
    raise self.exc_type(msg)
RuntimeError: Caught RuntimeError in replica 1 on device 1.
Original Traceback (most recent call last):
  File "/root/anaconda3/envs/pytorch/lib/python3.7/site-packages/torch/nn/parallel/parallel_apply.py", line 61, in _worker
    output = module(*input, **kwargs)
  File "/root/anaconda3/envs/pytorch/lib/python3.7/site-packages/torch/nn/modules/module.py", line 727, in _call_impl
    result = self.forward(*input, **kwargs)
  File "/userhome/root/workspace/chengyl/ours_barlow_rep_31/models/daml_c.py", line 321, in forward
    logits, feat_src = self._inner_forward(src_trn_data, OrderedDict(self.named_parameters()), 0)
  File "/userhome/root/workspace/chengyl/ours_barlow_rep_31/models/daml_c.py", line 101, in _inner_forward
    feat = self.encoder(x, get_child_dict(params, 'encoder'), episode)
  File "/root/anaconda3/envs/pytorch/lib/python3.7/site-packages/torch/nn/modules/module.py", line 727, in _call_impl
    result = self.forward(*input, **kwargs)
  File "/userhome/root/workspace/chengyl/ours_barlow_rep_31/models/encoders/resnet50.py", line 180, in forward
    out = self.conv1(x, get_child_dict(params, 'conv1'))
  File "/root/anaconda3/envs/pytorch/lib/python3.7/site-packages/torch/nn/modules/module.py", line 727, in _call_impl
    result = self.forward(*input, **kwargs)
  File "/userhome/root/workspace/chengyl/ours_barlow_rep_31/models/modules.py", line 82, in forward
    x = F.conv2d(x, weight, bias, self.stride, self.padding)
RuntimeError: cuDNN error: CUDNN_STATUS_NOT_INITIALIZED

terminate called after throwing an instance of 'c10::Error'
  what():  CUDA error: device-side assert triggered
Exception raised from create_event_internal at /opt/conda/conda-bld/pytorch_1607370141920/work/c10/cuda/CUDACachingAllocator.cpp:687 (most recent call first):
frame #0: c10::Error::Error(c10::SourceLocation, std::string) + 0x42 (0x7fd3b66fb8b2 in /root/anaconda3/envs/pytorch/lib/python3.7/site-packages/torch/lib/libc10.so)
frame #1: c10::cuda::CUDACachingAllocator::raw_delete(void*) + 0xad2 (0x7fd3b694d982 in /root/anaconda3/envs/pytorch/lib/python3.7/site-packages/torch/lib/libc10_cuda.so)
frame #2: c10::TensorImpl::release_resources() + 0x4d (0x7fd3b66e6b7d in /root/anaconda3/envs/pytorch/lib/python3.7/site-packages/torch/lib/libc10.so)
frame #3: <unknown function> + 0x5fea0a (0x7fd3f3a38a0a in /root/anaconda3/envs/pytorch/lib/python3.7/site-packages/torch/lib/libtorch_python.so)
frame #4: <unknown function> + 0x5feab6 (0x7fd3f3a38ab6 in /root/anaconda3/envs/pytorch/lib/python3.7/site-packages/torch/lib/libtorch_python.so)
<omitting python frames>
frame #21: __libc_start_main + 0xf3 (0x7fd40ec690b3 in /usr/lib/x86_64-linux-gnu/libc.so.6)

