0/60
libibverbs: Warning: couldn't open config directory '/etc/libibverbs.d'.
libibverbs: Warning: no userspace device-specific driver found for /sys/class/infiniband_verbs/uverbs1
libibverbs: Warning: no userspace device-specific driver found for /sys/class/infiniband_verbs/uverbs0
c Accuracy: 604/604 (100.0000%)

c Accuracy: 604/604 (100.0000%)

HNSW: 12.436920166015625
fine-tune:   0%|                                                                                                                               | 0/18 [00:00<?, ?it/s]                                                                                                                                                                      Traceback (most recent call last):
  File "train_da.py", line 837, in <module>
    train(config)
  File "train_da.py", line 489, in train
    loss, pull_loss, push_loss = model(trn_data, tst_data,inner_args,meta_train=True, mark=2,trn_flag=inner_flag, on_lbd=args.on_lbd, scale=args.push_scale, mmd_alpha=gamma)
  File "/userhome/anaconda3/envs/mfsan/lib/python3.6/site-packages/torch/nn/modules/module.py", line 889, in _call_impl
    result = self.forward(*input, **kwargs)
  File "/userhome/anaconda3/envs/mfsan/lib/python3.6/site-packages/torch/nn/parallel/data_parallel.py", line 167, in forward
    outputs = self.parallel_apply(replicas, inputs, kwargs)
  File "/userhome/anaconda3/envs/mfsan/lib/python3.6/site-packages/torch/nn/parallel/data_parallel.py", line 177, in parallel_apply
    return parallel_apply(replicas, inputs, kwargs, self.device_ids[:len(replicas)])
  File "/userhome/anaconda3/envs/mfsan/lib/python3.6/site-packages/torch/nn/parallel/parallel_apply.py", line 86, in parallel_apply
    output.reraise()
  File "/userhome/anaconda3/envs/mfsan/lib/python3.6/site-packages/torch/_utils.py", line 429, in reraise
    raise self.exc_type(msg)
RuntimeError: Caught RuntimeError in replica 0 on device 0.
Original Traceback (most recent call last):
  File "/userhome/anaconda3/envs/mfsan/lib/python3.6/site-packages/torch/nn/parallel/parallel_apply.py", line 61, in _worker
    output = module(*input, **kwargs)
  File "/userhome/anaconda3/envs/mfsan/lib/python3.6/site-packages/torch/nn/modules/module.py", line 889, in _call_impl
    result = self.forward(*input, **kwargs)
  File "/userhome/TNNLS/ours_barlow_rep_clef_4/models/daml_c.py", line 556, in forward
    p2_feat2 = self._outer_forward(pair2_tgt_data2, params, 0)
  File "/userhome/TNNLS/ours_barlow_rep_clef_4/models/daml_c.py", line 95, in _outer_forward
    feat = self.encoder(x, get_child_dict(params, 'encoder'), episode)
  File "/userhome/anaconda3/envs/mfsan/lib/python3.6/site-packages/torch/nn/modules/module.py", line 889, in _call_impl
    result = self.forward(*input, **kwargs)
  File "/userhome/TNNLS/ours_barlow_rep_clef_4/models/encoders/resnet50.py", line 189, in forward
    out = layer(out, get_child_dict(params, str(i)), episode)
  File "/userhome/anaconda3/envs/mfsan/lib/python3.6/site-packages/torch/nn/modules/module.py", line 889, in _call_impl
    result = self.forward(*input, **kwargs)
  File "/userhome/TNNLS/ours_barlow_rep_clef_4/models/encoders/resnet50.py", line 87, in forward
    out3 = self.conv3(out3, get_child_dict(params, 'conv3'))
  File "/userhome/anaconda3/envs/mfsan/lib/python3.6/site-packages/torch/nn/modules/module.py", line 889, in _call_impl
    result = self.forward(*input, **kwargs)
  File "/userhome/TNNLS/ours_barlow_rep_clef_4/models/modules.py", line 82, in forward
    x = F.conv2d(x, weight, bias, self.stride, self.padding)
RuntimeError: CUDA out of memory. Tried to allocate 14.00 MiB (GPU 0; 7.80 GiB total capacity; 6.51 GiB already allocated; 8.00 MiB free; 6.71 GiB reserved in total by PyTorch)

